<!DOCTYPE html>
<html lang="en">
<head>
    <meta charset="UTF-8">
    <title>Пользовательские ошибки, расширение Error</title>
    <link href="../../../style.css" rel="stylesheet">
</head>
<body>
    <article>
        <h2>Пользовательские ошибки, расширение Error</h2>
        <p>Когда что-то разрабатываем, то нам часто необходимы собственные классы ошибок для разных вещей, которые могут
        пойти не так в наших задачах. Для ошибок при работе с сетью может понадобиться <code>HttpError</code>, для
        операций с базой данных <code>DbError</code>, для поиска - <code>NotFoundError</code> и т.д.</p>
        <p>Наши ошибки должны поддерживать базовые свойства, такие как <code>message</code>, <code>name</code> и,
        желательно, <code>stack</code>. Но также они могут иметь свои собственные свойства. Например, объекты
        <code>HttpError</code> могут иметь свойство <code>statusCode</code> со значениями <code>404</code>,
        <code>403</code> или <code>500</code>.</p>
        <p>JavaScript позволяет вызывать <code>throw</code> с любыми аргументами, то есть технически наши классы
        ошибок не нуждаются в наследовании <code>Error</code>. Но если использовать наследование, то появляется
        возможность идентификации объектов ошибок посредством <code>obj instanceof Error</code>. Так что лучше применять
        наследование.</p>
        <p>По мере роста приложения, наши собственные ошибки образуют иерархию, например, <code>HttpTimeoutError</code>
        может наследовать от <code>HttpError</code> и так далее.</p>
    </article>

    <article>
        <h2>Расширение Error</h2>
        <p>В качестве примера рассмотрим функцию <code>readUser(json)</code>, которая должна читать данные пользователя
        в формате JSON.</p>
        <p>Пример того как может выглядеть корректный <code>json</code>:</p>
        <code>let json = '{"name": "John", "age": 30}';</code>
        <p>Внутри будем использовать <code>JSON.parse</code>. При получении некорректного <code>json</code> он будет
        генерировать ошибку <code>SyntaxError</code>. Но даже если <code>json</code> синтаксически верен, то это не значит,
        что это будет корректный пользователь, верно? Могут быть пропущены необходимые данные. Например, могут отсутствовать
        свойства <code>name</code> и <code>age</code>, который являются необходимыми для наших пользователей.</p>
        <p>Наша функция <code>readUser(json)</code> будет не только читать JSON-данные, но и проверять их
        («валидировать»). Если необходимые поля отсутствуют или данные в неверном формате, то это будет ошибкой.
        Но не синтаксической ошибкой <code>SyntaxError</code>, потому что данные синтаксически корректны. Это будет
        другая ошибка.</p>
        <p>Назовем ее ошибкой валидации <code>ValidationError</code> и создадим для нее класс. Ошибка этого вида
        должна содержать информацию о поле, которое является источником ошибки.</p>
        <p>Наш класс <code>ValidationError</code> должен наследовать от встроенного класса <code>Error</code>.</p>
        <p>Класс <code>Error</code> встроенный, вот его примерный код, просто чтобы мы понимали что расширяем:</p>
        <code>
            // Псевдокод встроенного класса Error, определенного самим JavaScript<br>
            class Error {<br>
            &nbsp;&nbsp;constructor(message) {<br>
            &nbsp;&nbsp;&nbsp;&nbsp;this.message = message;<br>
            &nbsp;&nbsp;&nbsp;&nbsp;this.name = 'Error'; // (Разные имена для разных встроенных классов ошибок)<br>
            &nbsp;&nbsp;&nbsp;&nbsp;this.stack = &ltстек вызовов&gt;; // Нестандартное свойство, но обычно поддерживается<br>
            &nbsp;&nbsp;}<br>
            }
        </code>
        <p>Теперь давайте унаследуем от него <code>ValidationError</code> и попробуем новый класс в действии:</p>
        <code>
            class ValidationError extends Error {<br>
            &nbsp;&nbsp;constructor(message) {<br>
            &nbsp;&nbsp;&nbsp;&nbsp;super(message); // (1)<br>
            &nbsp;&nbsp;&nbsp;&nbsp;this.name = 'ValidationError'; // (2)<br>
            &nbsp;&nbsp;}<br>
            }<br>
            <br>
            function test() {<br>
            &nbsp;&nbsp;throw new ValidationError('Упс!');<br>
            }<br>
            <br>
            try {<br>
            &nbsp;&nbsp;test();<br>
            } catch(err) {<br>
            &nbsp;&nbsp;alert(err.message); // Упс!<br>
            &nbsp;&nbsp;alert(err.name); // ValidationError<br>
            &nbsp;&nbsp;alert(err.stack); // Список вложенных вызовов с номерами строк для каждого<br>
            }
        </code>
        <p>Обратите внимание: в строке <code>(1)</code> вызываем родительский конструктор. JavaScript требует от нас
        вызова <code>super</code> в дочернем конструкторе, так что это обязательно. Родительский конструктор устанавливает
        свойство <code>message</code>.</p>
        <p>Родительский конструктор также устанавливает свойство <code>name</code> для <code>'Error'</code>, поэтому
        в строке <code>(2)</code> мы сбрасываем его на правильное значение.</p>
        <p>Попробуем использовать его в <code>readUser(json)</code>:</p>
        <code>
            class ValidationError extends Error {<br>
            &nbsp;&nbsp;constructor(message) {<br>
            &nbsp;&nbsp;&nbsp;&nbsp;super(message);<br>
            &nbsp;&nbsp;&nbsp;&nbsp;this.name = 'ValidationError'<br>
            &nbsp;&nbsp;}<br>
            }<br>
            <br>
            // Использование<br>
            function readUser(json) {<br>
            &nbsp;&nbsp;let user = JSON.parse(json);<br>
            <br>
            &nbsp;&nbsp;if (!user.age) {<br>
            &nbsp;&nbsp;&nbsp;&nbsp;throw new ValidationError('Нет поля: age');<br>
            &nbsp;&nbsp;}<br>
            <br>
            &nbsp;&nbsp;if (!user.name) {<br>
            &nbsp;&nbsp;&nbsp;&nbsp;throw new ValidationError('Нет поля: name');<br>
            &nbsp;&nbsp;}<br>
            <br>
            &nbsp;&nbsp;return user;<br>
            }<br>
            <br>
            // Рабочий пример с try...catch<br>
            <br>
            try {<br>
            &nbsp;&nbsp;let user = readUser('{"age": 25}');<br>
            } catch(err) {<br>
            &nbsp;&nbsp;if (err instanceof ValidationError) {<br>
            &nbsp;&nbsp;&nbsp;&nbsp;alert('Некорректные данные: ' + err.message); // Некорректные данные: Нет поля: name<br>
            &nbsp;&nbsp;} else if (err instanceof SyntaxError) { // (*)<br>
            &nbsp;&nbsp;&nbsp;&nbsp;alert('JSON Ошибка синтаксиса: + err.message);<br>
            &nbsp;&nbsp;} else {<br>
            &nbsp;&nbsp;&nbsp;&nbsp;throw err; // Неизвестная ошибка, пробросить исключение (**)<br>
            &nbsp;&nbsp;}<br>
            }
        </code>
        <p>Блок <code>try...catch</code> в коде выше обрабатывает и нашу <code>ValidationError</code>, и встроенную
        <code>SyntaxError</code> из <code>JSON.parse</code>.</p>
        <p>Обратите внимание, как мы используем <code>instanceof</code> для проверки конкретного типа ошибки в строке
        <code>(*)</code>.</p>
        <p>Мы также можем проверить тип, используя <code>err.name</code>:</p>
        <code>
            // ...<br>
            // Вместо (err instanceof SyntaxError)<br>
            } else if (err.name === 'SyntaxError') { // (*)<br>
            // ...
        </code>
        <p>Версия с <code>instanceof</code> гораздо лучше, потому что в будущем мы собираемся расширить
        <code>ValidationError</code>, сделав его подтипы, такие как <code>PropertyRequiredError</code>. И проверка
        <code>instanceof</code> продолжит работать для новых наследованных классов.</p>
        <p>Также важно, что если <code>catch</code> встречает неизвестную ошибку, то она пробрасывает ее в строке
        <code>(**)</code>. Блок <code>catch</code> знает, только как обрабатывать ошибки валидации и синтаксические ошибки,
        а другие виды ошибок (из-за опечаток в коде и другие непонятные) он должен выпустить наружу.</p>
    </article>

    <article>
        <h2>Дальнейшее наследование</h2>
        <p>Класс <code>ValidationError</code> является слишком общим. Много что может пойти не так. Свойство может
        отсутствовать или иметь неверный формат (например, строка как значение возраста <code>age</code>). Поэтому для
        отсутствующих свойств сделаем более конкретный класс <code>PropertyRequiredError</code>. Он будет нести
        дополнительную информацию о свойстве, которое отсутствует.</p>
        <code>
            class ValidationError extends Error {<br>
            &nbsp;&nbsp;constructor(message) {<br>
            &nbsp;&nbsp;&nbsp;&nbsp;super(message);<br>
            &nbsp;&nbsp;&nbsp;&nbsp;this.name = 'ValidationError';<br>
            &nbsp;&nbsp;}<br>
            }<br>
            <br>
            class PropertyRequiredError extends ValidationError {<br>
            &nbsp;&nbsp;constructor(property) {<br>
            &nbsp;&nbsp;&nbsp;&nbsp;super('Нет свойства: ' + property);<br>
            &nbsp;&nbsp;&nbsp;&nbsp;this.name = 'PropertyRequiredError';<br>
            &nbsp;&nbsp;&nbsp;&nbsp;this.property = property;<br>
            &nbsp;&nbsp;}<br>
            }<br>
            <br>
            // Применение<br>
            function readUser(json) {<br>
            &nbsp;&nbsp;let user = JSON.parse(json);<br>
            <br>
            &nbsp;&nbsp;if (!user.age) {<br>
            &nbsp;&nbsp;&nbsp;&nbsp;throw new PropertyRequiredError('age');<br>
            &nbsp;&nbsp;}<br>
            <br>
            &nbsp;&nbsp;if (!user.name) {<br>
            &nbsp;&nbsp;&nbsp;&nbsp;throw new PropertyRequiredError('name');<br>
            &nbsp;&nbsp;}<br>
            <br>
            &nbsp;&nbsp;return user;<br>
            }<br>
            <br>
            // Рабочий пример с try...catch<br>
            try {<br>
            &nbsp;&nbsp;let user = readUser('{"age": 25}');<br>
            } catch(err) {<br>
            &nbsp;&nbsp;if (err instanceof ValidationError) {<br>
            &nbsp;&nbsp;&nbsp;&nbsp;alert('Неверные данные: ' + err.message); // Неверные данные: Нет свойства: name<br>
            &nbsp;&nbsp;&nbsp;&nbsp;alert(err.name); // PropertyRequiredError<br>
            &nbsp;&nbsp;&nbsp;&nbsp;alert(err.property); // name<br>
            &nbsp;&nbsp;} else if (err instanceof SyntaxError) {<br>
            &nbsp;&nbsp;&nbsp;&nbsp;alert('Ошибка синтаксиса JSON: ' + err.message);<br>
            &nbsp;&nbsp;} else {<br>
            &nbsp;&nbsp;&nbsp;&nbsp;throw err; // Неизвестная ошибка, повторно выбросит исключение<br>
            &nbsp;&nbsp;}<br>
            }
        </code>
        <p>Новый класс <code>PropertyRequiredError</code> очень просто использовать: необходимо указать только имя
        свойства <code>new PropertyRequiredError(property)</code>. Сообщение для пользователя <code>message</code>
        генерируется конструктором.</p>
        <p>Обратите внимание, что свойство <code>this.name</code> в конструкторе <code>PropertyRequiredError</code> снова
        присвоено вручную. Правда, немного утомительно - присваивать <code>this.name = &ltclass name&gt</code> в каждом
        классе пользовательской ошибки. Можно этого избежать, если сделать наш собственный «базовый» класс ошибки,
        который будет ставить <code>this.name = this.constructor.name</code>. И затем наследовать все ошибки уже от него.</p>
        <p>Давайте назовем его <code>MyError</code>.</p>
        <p>Вот упрощенный код с <code>MyError</code> и другими пользовательскими классами ошибок:</p>
        <code>
            class MyError extends Error {<br>
            &nbsp;&nbsp;constructor(message) {<br>
            &nbsp;&nbsp;&nbsp;&nbsp;super(message);<br>
            &nbsp;&nbsp;&nbsp;&nbsp;this.name = this.constructor.name;<br>
            &nbsp;&nbsp;}<br>
            }<br>
            <br>
            class ValidationError extends MyError {}<br>
            <br>
            class PropertyRequiredError extends ValidationError {<br>
            &nbsp;&nbsp;constructor(property) {<br>
            &nbsp;&nbsp;&nbsp;&nbsp;super('Нет свойства: ' + property);<br>
            &nbsp;&nbsp;&nbsp;&nbsp;this.property = property;<br>
            &nbsp;&nbsp;}<br>
            }<br>
            <br>
            // name корректное<br>
            alert(new PropertyRequiredError().name); // PropertyRequiredError
        </code>
        <p>Теперь пользовательские ошибки стали намного короче, особенно <code>ValidationError</code>, так как мы
        избавились от строки <code>this.name = 'ErrorName'</code> в конструкторе.</p>
    </article>

    <article>
        <h2>Обертывание исключений</h2>
        <p>Назначение функции <code>readUser</code> в приведенном выше коде - это «чтение данных пользователя».
        В процессе могут возникнуть различные виды ошибок. Сейчас у нас есть <code>SyntaxError</code> и
        <code>ValidationError</code>, но в будущем функция <code>readUser</code> может расшириться и, возможно,
        генерировать другие виды ошибок.</p>
        <p>Код, который вызывает <code>readUser</code>, должен обрабатывать эти ошибки.</p>
        <p>Сейчас в нем используются проверки <code>if</code> в блоке <code>catch</code>, которые проверяют класс
        и обрабатывают известные ошибки и пробрасывают дальше неизвестные. Но если функция <code>readUser</code> генерирует
        несколько видов ошибок, то мы должны спросить себя: действительно ли мы хотим проверять все типы ошибок
        поодиночке во всех местах в коде, где вызывается <code>readUser</code>?</p>
        <p>Часто ответ «Нет»: внешний код хочет быть на один уровень выше всего этого. Он хочет иметь какую-то обобщенную
        ошибку чтения данных. Почему именно это произошло - часто не имеет значения (об этом говорится в сообщении об
        ошибке). Или даже лучше, если есть способ получить подробности об ошибке, но только если нам это нужно.</p>
        <p>Итак, давайте создадим новый класс <code>ReadError</code> для представления таких ошибок. Если ошибка возникает
        внутри <code>readUser</code>, мы ее перехватим и сгенерируем <code>ReadError</code>. Мы также сохраним ссылку на
        исходную ошибку в свойстве <code>cause</code>. Тогда внешний код должен только проверить наличие <code>ReadError</code>.</p>
        <p>Этот код определяет ошибку <code>ReadError</code> и демонстрирует ее использование в <code>readUser</code>
        и <code>try...catch</code>:</p>
        <code>
            class ReadError extends Error {<br>
            &nbsp;&nbsp;constructor(message, cause) {<br>
            &nbsp;&nbsp;&nbsp;&nbsp;super(message);<br>
            &nbsp;&nbsp;&nbsp;&nbsp;this.cause = cause;<br>
            &nbsp;&nbsp;&nbsp;&nbsp;this.name = 'ReadError';<br>
            &nbsp;&nbsp;}<br>
            }<br>
            <br>
            class ValidationError extends Error {/*...*/}<br>
            class PropertyRequiredError extends ValidationError {/*...*/}<br>
            <br>
            function validateUser(user) {<br>
            &nbsp;&nbsp;if (!user.age) {<br>
            &nbsp;&nbsp;&nbsp;&nbsp;throw new PropertyRequiredError('age');<br>
            &nbsp;&nbsp;}<br>
            <br>
            &nbsp;&nbsp;if (!user.name) {<br>
            &nbsp;&nbsp;&nbsp;&nbsp;throw new PropertyRequiredError('name');<br>
            &nbsp;&nbsp;}<br>
            }<br>
            <br>
            function readUser(json) {<br>
            &nbsp;&nbsp;let user;<br>
            <br>
            &nbsp;&nbsp;try {<br>
            &nbsp;&nbsp;&nbsp;&nbsp;user = JSON.parse(json);<br>
            &nbsp;&nbsp;} catch(err) {<br>
            &nbsp;&nbsp;&nbsp;&nbsp;if (err instanceof SyntaxError) {<br>
            &nbsp;&nbsp;&nbsp;&nbsp;&nbsp;&nbsp;throw new ReadError('Синтаксическая ошибка', err);<br>
            &nbsp;&nbsp;&nbsp;&nbsp;} else {<br>
            &nbsp;&nbsp;&nbsp;&nbsp;&nbsp;&nbsp;throw err;<br>
            &nbsp;&nbsp;&nbsp;&nbsp;}<br>
            &nbsp;&nbsp;}<br>
            <br>
            &nbsp;&nbsp;try {<br>
            &nbsp;&nbsp;&nbsp;&nbsp;validateUser(user);<br>
            &nbsp;&nbsp;catch(err) {<br>
            &nbsp;&nbsp;&nbsp;&nbsp;if (err instanceof ValidationError) {<br>
            &nbsp;&nbsp;&nbsp;&nbsp;&nbsp;&nbsp;throw new ReadError('Ошибка валидации', err);<br>
            &nbsp;&nbsp;&nbsp;&nbsp;} else {<br>
            &nbsp;&nbsp;&nbsp;&nbsp;&nbsp;&nbsp;throw err;<br>
            &nbsp;&nbsp;&nbsp;&nbsp;}<br>
            &nbsp;&nbsp;}<br>
            }<br>
            <br>
            try {<br>
            &nbsp;&nbsp;readUser('{bad json}');<br>
            } catch(err) {<br>
            &nbsp;&nbsp;if (err instanceof ReadError) {<br>
            &nbsp;&nbsp;&nbsp;&nbsp;alert(err)<br>
            &nbsp;&nbsp;&nbsp;&nbsp;// Исходная ошибка: SyntaxError: unexpected token b in JSON at position 1<br>
            &nbsp;&nbsp;&nbsp;&nbsp;alert('Исходная ошибка: ' + err.cause);<br>
            &nbsp;&nbsp;} else {<br>
            &nbsp;&nbsp;&nbsp;&nbsp;throw e;<br>
            &nbsp;&nbsp;}<br>
            }
        </code>
        <p>В приведенном выше коде <code>readUser</code> работает так, как описано - функция распознает синтаксические
        ошибки и ошибки валидации и выдает вместо них ошибки <code>ReadError</code> (неизвестные ошибки, как обычно,
        пробрасываются).</p>
        <p>Внешний код проверяет только <code>ReadError</code>. Ну нужно перечислять все возможные типы ошибок.</p>
        <p>Этот подход называется «обертывание исключений», потому что мы берем «исключение низкого уровня» и
        «оборачиваем» их в <code>ReadError</code>, который является более абстрактным и более удобным для использования
        в вызывающем коде. Такой подход широко используется в объектно-ориентированном программировании.</p>
    </article>

    <article>
        <h2>Итого</h2>
        <ul>
            <li>
                <p>Мы можем наследовать свои классы ошибок от <code>Error</code> и других встроенных классов ошибок,
                но нужно позаботиться о свойстве <code>name</code> и не забывать вызывать <code>super</code>.</p>
            </li>
            <li>
                <p>Мы можем использовать <code>instanceof</code> для проверки типа ошибок. Это также сработает с
                наследованием. Но иногда у нас объект ошибки, возникшей в сторонней библиотеке, и нет простого способа
                получить класс. Тогда для проверки типа ошибки можно использовать свойство <code>name</code>.</p>
            </li>
            <li>
                <p>Обертывание исключений является распространенной техникой: функция ловит низкоуровневые исключения
                и создает одно «высокоуровневое» исключение вместо разных низкоуровневых. Иногда низкоуровневые
                исключения становятся свойствами этого объекта, как <code>err.cause</code> в примерах выше,
                но это не обязательно.</p>
            </li>
        </ul>
    </article>
</body>
</html>

<script src="script.js"></script>